<?xml version="1.0" ?>


<robot name="experiment">
    <!-- Materials -->
    <material name="yellow">
        <color rgba="1 1 0 0.5"/>
    </material>
    <material name="red">
        <color rgba="1 0 0 0.5"/>
    </material>
    <material name="blue">
        <color rgba="0 0 1 0.5"/>
    </material>
    <material name="white">
        <color rgba="0 0 0 0.5"/>
    </material>
    <material name="black">
        <color rgba="1 1 1 0.5"/>
    </material>

    <!-- Gazebo tags -->
    <!-- <gazebo reference="base_link">
        <material>Gazebo/Blue</material>
    </gazebo> -->

    <!-- Links -->

    <!--Link: base_footprint-->
    <link name="base_footprint">
        <visual>
            <geometry>
                <cylinder length="0.001" radius="0.25"/>
            </geometry>
            <material name="yellow" />
        </visual>
    </link>

    <!--Link: base_link-->
    <link name="base_link">
        <!-- <inertial>
            <origin xyz="0 0 0" rpy="0 0 0"/>
            <mass value="25"/>
            <inertia ixx="0" ixy="0" ixz="0" iyy="0" iyz="0" izz="0"/>
        </inertial> -->

        <collision>
            <!-- <origin xyz="0 0 0.15" rpy="0 0 0"/> -->
            <geometry>
                <cylinder length="0.3" radius="0.25"/>
                <!-- <sphere radius=""/> -->
            </geometry>
        </collision>

        <visual>
            <!-- <origin xyz="1 1 0.15" rpy="0 0 0"/> -->
            <geometry>
                <cylinder length="0.3" radius="0.25"/>
                <!-- <sphere radius=""/> -->
            </geometry>
            <material name="blue" />
        </visual>
    </link>

    <!--Link: right_wheel-->
    <link name="right_wheel">
        <!-- <inertial>
            <origin xyz="0 0 0" rpy="0 0 0"/>
            <mass value="25"/>
            <inertia ixx="0" ixy="0" ixz="0" iyy="0" iyz="0" izz="0"/>
        </inertial> -->

        <collision>
            <!-- <origin xyz="0 0 0.15" rpy="0 0 0"/> -->
            <geometry>
                <cylinder length="0.025" radius="0.025"/>
                <!-- <sphere radius=""/> -->
            </geometry>
        </collision>

        <visual>
            <!-- <origin xyz="1 1 0.15" rpy="0 0 0"/> -->
            <geometry>
                <cylinder length="0.025" radius="0.025"/>
                <!-- <sphere radius=""/> -->
            </geometry>
            <material name="red" />
        </visual>
    </link>

    <!--Link: left_wheel-->
    <link name="left_wheel">
        <!-- <inertial>
            <origin xyz="0 0 0" rpy="0 0 0"/>
            <mass value="25"/>
            <inertia ixx="0" ixy="0" ixz="0" iyy="0" iyz="0" izz="0"/>
        </inertial> -->

        <collision>
            <!-- <origin xyz="0 0 0.15" rpy="0 0 0"/> -->
            <geometry>
                <cylinder length="0.025" radius="0.025"/>
                <!-- <sphere radius=""/> -->
            </geometry>
        </collision>

        <visual>
            <!-- <origin xyz="1 1 0.15" rpy="0 0 0"/> -->
            <geometry>
                <cylinder length="0.025" radius="0.025"/>
                <!-- <sphere radius=""/> -->
            </geometry>
            <material name="red" />
        </visual>
    </link>

    <!--Link: front_caster-->
    <link name="front_caster">
        <!-- <inertial>
            <origin xyz="0 0 0" rpy="0 0 0"/>
            <mass value="25"/>
            <inertia ixx="0" ixy="0" ixz="0" iyy="0" iyz="0" izz="0"/>
        </inertial> -->

        <!-- Outer wheel -->
        <collision>
            <origin xyz="0 0 0.005" rpy="0 0 0"/>
            <geometry>
                <sphere radius="0.025"/>
            </geometry>
        </collision>

        <visual>
            <origin xyz="0 0 0.005" rpy="0 0 0"/>
            <geometry>
                <sphere radius="0.025"/>
            </geometry>
            <material name="blue" />
        </visual>

        <!-- Inner wheel -->
        <collision>
            <origin xyz="0 0 -0.015" rpy="0 0 0"/>
            <geometry>
                <sphere radius="0.015"/>
            </geometry>
        </collision>

        <visual>
            <origin xyz="0 0 -0.01" rpy="0 0 0"/>
            <geometry>
                <sphere radius="0.015"/>
            </geometry>
            <material name="white" />
        </visual>
    </link>

    <!--Link: rear_caster-->
    <link name="rear_caster">
        <!-- <inertial>
            <origin xyz="0 0 0" rpy="0 0 0"/>
            <mass value="25"/>
            <inertia ixx="0" ixy="0" ixz="0" iyy="0" iyz="0" izz="0"/>
        </inertial> -->

        <!-- Outer wheel -->
        <collision>
            <origin xyz="0 0 0.005" rpy="0 0 0"/>
            <geometry>
                <sphere radius="0.025"/>
            </geometry>
        </collision>

        <visual>
            <origin xyz="0 0 0.005" rpy="0 0 0"/>
            <geometry>
                <sphere radius="0.025"/>
            </geometry>
            <material name="blue" />
        </visual>

        <!-- Inner wheel -->
        <collision>
            <origin xyz="0 0 -0.015" rpy="0 0 0"/>
            <geometry>
                <sphere radius="0.015"/>
            </geometry>
        </collision>

        <visual>
            <origin xyz="0 0 -0.01" rpy="0 0 0"/>
            <geometry>
                <sphere radius="0.015"/>
            </geometry>
            <material name="white" />
        </visual>
    </link>

    <!--Link: front_laser-->
    <link name="front_laser">
        <!-- <inertial>
            <origin xyz="0 0 0" rpy="0 0 0"/>
            <mass value="25"/>
            <inertia ixx="0" ixy="0" ixz="0" iyy="0" iyz="0" izz="0"/>
        </inertial> -->

        <collision>
            <!-- <origin xyz="0 0 0.15" rpy="0 0 0"/> -->
            <geometry>
                <cylinder length="0.025" radius="0.025"/>
                <!-- <sphere radius=""/> -->
            </geometry>
        </collision>

        <visual>
            <!-- <origin xyz="1 1 0.15" rpy="0 0 0"/> -->
            <geometry>
                <cylinder length="0.025" radius="0.025"/>
                <!-- <sphere radius=""/> -->
            </geometry>
            <material name="black" />
        </visual>
    </link>


    <!-- Joints -->
    <!-- <joint name="" type="">
        <origin xyz="0 0 0" rpy="0 0 0" />
        <parent link="" />
        <child link="" />
        <axis xyz="0 0 0" rpy="0 0 0" />
        <limit effort="0" velocity="0" />
        <joint_properties damping="0" friction="0" />
    </joint> -->

    <!--Joint: base_footprint/base_link-->
    <joint name="joint_base_footprint_base_link" type="fixed">
        <origin xyz="0 0 0.15" rpy="0 0 0" />
        <parent link="base_footprint" />
        <child link="base_link" />
    </joint>

    <!--Joint: base_link/right_wheel-->
    <joint name="joint_base_link_right_wheel" type="continuous">
        <origin xyz="0 -0.2 -0.15" rpy="1.5708 0 0" />
        <parent link="base_link" />
        <child link="right_wheel" />
        <axis xyz="0 0 1" rpy="0 0 0" />
        <limit effort="1000" velocity="1000" /> <!-- ? -->
        <joint_properties damping="1.0" friction="1.0" /> <!-- ? -->
    </joint>

    <!--Joint: base_link/left_wheel-->
    <joint name="joint_base_link_left_wheel" type="continuous">
        <origin xyz="0 0.2 -0.15" rpy="1.5708 0 0" />
        <parent link="base_link" />
        <child link="left_wheel" />
        <axis xyz="0 0 1" rpy="0 0 0" />
        <limit effort="1000" velocity="1000" /> <!-- ? -->
        <joint_properties damping="1.0" friction="1.0" /> <!-- ? -->
    </joint>

    <!--Joint: base_link/front_caster-->
    <joint name="joint_base_link_front_caster" type="fixed">
        <origin xyz="0.1 0.0 -0.15" rpy="0 0 0" />
        <parent link="base_link" />
        <child link="front_caster" />
        <joint_properties damping="1.0" friction="0.0" /> <!-- ? -->
    </joint>

    <!--Joint: base_link/rear_caster-->
    <joint name="joint_base_link_rear_caster" type="fixed">
        <origin xyz="-0.1 0.0 -0.15" rpy="0 0 0" />
        <parent link="base_link" />
        <child link="rear_caster" />
        <joint_properties damping="1.0" friction="0.0" /> <!-- ? -->
    </joint>

    
    <!--Joint: base_link/front_laser-->
    <joint name="joint_base_link_front_laser" type="fixed">
        <origin xyz="0.25 0.0 0.075" rpy="3.14159 0 0" />
        <parent link="base_link" />
        <child link="front_laser" />
    </joint>
</robot>